2020-02-12 03:51:53,075 ERROR: Exception on /user/yuhyun934 [GET] [in c:\users\april\documents\flask\item_tracker\venv\lib\site-packages\flask\app.py:1891]
Traceback (most recent call last):
  File "c:\users\april\documents\flask\item_tracker\venv\lib\site-packages\flask\app.py", line 2446, in wsgi_app
    response = self.full_dispatch_request()
  File "c:\users\april\documents\flask\item_tracker\venv\lib\site-packages\flask\app.py", line 1951, in full_dispatch_request
    rv = self.handle_user_exception(e)
  File "c:\users\april\documents\flask\item_tracker\venv\lib\site-packages\flask\app.py", line 1820, in handle_user_exception
    reraise(exc_type, exc_value, tb)
  File "c:\users\april\documents\flask\item_tracker\venv\lib\site-packages\flask\_compat.py", line 39, in reraise
    raise value
  File "c:\users\april\documents\flask\item_tracker\venv\lib\site-packages\flask\app.py", line 1949, in full_dispatch_request
    rv = self.dispatch_request()
  File "c:\users\april\documents\flask\item_tracker\venv\lib\site-packages\flask\app.py", line 1935, in dispatch_request
    return self.view_functions[rule.endpoint](**req.view_args)
  File "c:\users\april\documents\flask\item_tracker\venv\lib\site-packages\flask_login\utils.py", line 261, in decorated_view
    return func(*args, **kwargs)
  File "C:\Users\April\Documents\GitHub\item_tracker\app\routes.py", line 78, in user
    return render_template('user.html', user=user, posts=posts.items, next_url=next_url, prev_url=prev_url)
  File "c:\users\april\documents\flask\item_tracker\venv\lib\site-packages\flask\templating.py", line 138, in render_template
    ctx.app.jinja_env.get_or_select_template(template_name_or_list),
  File "c:\users\april\documents\flask\item_tracker\venv\lib\site-packages\jinja2\environment.py", line 869, in get_or_select_template
    return self.get_template(template_name_or_list, parent, globals)
  File "c:\users\april\documents\flask\item_tracker\venv\lib\site-packages\jinja2\environment.py", line 830, in get_template
    return self._load_template(name, self.make_globals(globals))
  File "c:\users\april\documents\flask\item_tracker\venv\lib\site-packages\jinja2\environment.py", line 804, in _load_template
    template = self.loader.load(self, name, globals)
  File "c:\users\april\documents\flask\item_tracker\venv\lib\site-packages\jinja2\loaders.py", line 125, in load
    code = environment.compile(source, name, filename)
  File "c:\users\april\documents\flask\item_tracker\venv\lib\site-packages\jinja2\environment.py", line 591, in compile
    self.handle_exception(exc_info, source_hint=source_hint)
  File "c:\users\april\documents\flask\item_tracker\venv\lib\site-packages\jinja2\environment.py", line 780, in handle_exception
    reraise(exc_type, exc_value, tb)
  File "c:\users\april\documents\flask\item_tracker\venv\lib\site-packages\jinja2\_compat.py", line 37, in reraise
    raise value.with_traceback(tb)
  File "C:\Users\April\Documents\GitHub\item_tracker\app\templates\user.html", line 26, in template
    {% endif %}
  File "c:\users\april\documents\flask\item_tracker\venv\lib\site-packages\jinja2\environment.py", line 497, in _parse
    return Parser(self, source, name, encode_filename(filename)).parse()
  File "c:\users\april\documents\flask\item_tracker\venv\lib\site-packages\jinja2\parser.py", line 901, in parse
    result = nodes.Template(self.subparse(), lineno=1)
  File "c:\users\april\documents\flask\item_tracker\venv\lib\site-packages\jinja2\parser.py", line 883, in subparse
    rv = self.parse_statement()
  File "c:\users\april\documents\flask\item_tracker\venv\lib\site-packages\jinja2\parser.py", line 130, in parse_statement
    return getattr(self, 'parse_' + self.stream.current.value)()
  File "c:\users\april\documents\flask\item_tracker\venv\lib\site-packages\jinja2\parser.py", line 268, in parse_block
    node.body = self.parse_statements(('name:endblock',), drop_needle=True)
  File "c:\users\april\documents\flask\item_tracker\venv\lib\site-packages\jinja2\parser.py", line 170, in parse_statements
    self.fail_eof(end_tokens)
  File "c:\users\april\documents\flask\item_tracker\venv\lib\site-packages\jinja2\parser.py", line 104, in fail_eof
    return self._fail_ut_eof(None, stack, lineno)
  File "c:\users\april\documents\flask\item_tracker\venv\lib\site-packages\jinja2\parser.py", line 90, in _fail_ut_eof
    self.fail(' '.join(message), lineno)
  File "c:\users\april\documents\flask\item_tracker\venv\lib\site-packages\jinja2\parser.py", line 59, in fail
    raise exc(msg, lineno, self.name, self.filename)
jinja2.exceptions.TemplateSyntaxError: Unexpected end of template. Jinja was looking for the following tags: 'endblock'. The innermost block that needs to be closed is 'block'.
2020-02-12 03:52:48,855 INFO: Microblog startup [in C:\Users\April\Documents\GitHub\item_tracker\app\__init__.py:44]
2020-02-19 11:56:53,492 INFO: Microblog startup [in C:\Users\April\Documents\GitHub\item_tracker\app\__init__.py:44]
2020-03-03 15:51:04,378 INFO: Microblog startup [in C:\Users\April\Documents\GitHub\item_tracker\app\__init__.py:44]
2020-03-03 21:56:25,597 INFO: Microblog startup [in C:\Users\April\Documents\GitHub\item_tracker\app\__init__.py:44]
2020-03-03 21:59:13,254 ERROR: Exception on /user/yuhyun934 [GET] [in c:\users\april\documents\flask\item_tracker\venv\lib\site-packages\flask\app.py:1891]
Traceback (most recent call last):
  File "c:\users\april\documents\flask\item_tracker\venv\lib\site-packages\flask\app.py", line 2446, in wsgi_app
    response = self.full_dispatch_request()
  File "c:\users\april\documents\flask\item_tracker\venv\lib\site-packages\flask\app.py", line 1951, in full_dispatch_request
    rv = self.handle_user_exception(e)
  File "c:\users\april\documents\flask\item_tracker\venv\lib\site-packages\flask\app.py", line 1820, in handle_user_exception
    reraise(exc_type, exc_value, tb)
  File "c:\users\april\documents\flask\item_tracker\venv\lib\site-packages\flask\_compat.py", line 39, in reraise
    raise value
  File "c:\users\april\documents\flask\item_tracker\venv\lib\site-packages\flask\app.py", line 1949, in full_dispatch_request
    rv = self.dispatch_request()
  File "c:\users\april\documents\flask\item_tracker\venv\lib\site-packages\flask\app.py", line 1935, in dispatch_request
    return self.view_functions[rule.endpoint](**req.view_args)
  File "c:\users\april\documents\flask\item_tracker\venv\lib\site-packages\flask_login\utils.py", line 261, in decorated_view
    return func(*args, **kwargs)
  File "C:\Users\April\Documents\GitHub\item_tracker\app\routes.py", line 78, in user
    return render_template('user.html', user=user, posts=posts.items, next_url=next_url, prev_url=prev_url)
  File "c:\users\april\documents\flask\item_tracker\venv\lib\site-packages\flask\templating.py", line 140, in render_template
    ctx.app,
  File "c:\users\april\documents\flask\item_tracker\venv\lib\site-packages\flask\templating.py", line 120, in _render
    rv = template.render(context)
  File "c:\users\april\documents\flask\item_tracker\venv\lib\site-packages\jinja2\asyncsupport.py", line 76, in render
    return original_render(self, *args, **kwargs)
  File "c:\users\april\documents\flask\item_tracker\venv\lib\site-packages\jinja2\environment.py", line 1008, in render
    return self.environment.handle_exception(exc_info, True)
  File "c:\users\april\documents\flask\item_tracker\venv\lib\site-packages\jinja2\environment.py", line 780, in handle_exception
    reraise(exc_type, exc_value, tb)
  File "c:\users\april\documents\flask\item_tracker\venv\lib\site-packages\jinja2\_compat.py", line 37, in reraise
    raise value.with_traceback(tb)
  File "C:\Users\April\Documents\GitHub\item_tracker\app\templates\user.html", line 1, in top-level template code
    {% extends "base.html" %}
  File "c:\users\april\documents\flask\item_tracker\venv\lib\site-packages\jinja2\environment.py", line 1005, in render
    return concat(self.root_render_func(self.new_context(vars)))
  File "C:\Users\April\Documents\GitHub\item_tracker\app\templates\user.html", line 14, in root
    {% elif not current_user.is_following(user) %}
  File "C:\Users\April\Documents\GitHub\item_tracker\app\templates\base.html", line 55, in root
  File "C:\Users\April\Documents\GitHub\item_tracker\app\templates\user.html", line 54, in block_content
  File "c:\users\april\documents\flask\item_tracker\venv\lib\site-packages\jinja2\runtime.py", line 262, in call
    return __obj(*args, **kwargs)
  File "c:\users\april\documents\flask\item_tracker\venv\lib\site-packages\flask\helpers.py", line 370, in url_for
    return appctx.app.handle_url_build_error(error, endpoint, values)
  File "c:\users\april\documents\flask\item_tracker\venv\lib\site-packages\flask\app.py", line 2215, in handle_url_build_error
    reraise(exc_type, exc_value, tb)
  File "c:\users\april\documents\flask\item_tracker\venv\lib\site-packages\flask\_compat.py", line 39, in reraise
    raise value
  File "c:\users\april\documents\flask\item_tracker\venv\lib\site-packages\flask\helpers.py", line 358, in url_for
    endpoint, values, method=method, force_external=external
  File "c:\users\april\documents\flask\item_tracker\venv\lib\site-packages\werkzeug\routing.py", line 2020, in build
    raise BuildError(endpoint, values, method, self)
werkzeug.routing.BuildError: Could not build url for endpoint 'follow' with values ['username']. Did you mean 'login' instead?
