2020-03-04 18:03:46,340 ERROR: Exception on /index [GET] [in c:\users\aevix\appdata\local\programs\python\python37\lib\site-packages\flask\app.py:1891]
Traceback (most recent call last):
  File "c:\users\aevix\appdata\local\programs\python\python37\lib\site-packages\flask\app.py", line 2446, in wsgi_app
    response = self.full_dispatch_request()
  File "c:\users\aevix\appdata\local\programs\python\python37\lib\site-packages\flask\app.py", line 1951, in full_dispatch_request
    rv = self.handle_user_exception(e)
  File "c:\users\aevix\appdata\local\programs\python\python37\lib\site-packages\flask\app.py", line 1820, in handle_user_exception
    reraise(exc_type, exc_value, tb)
  File "c:\users\aevix\appdata\local\programs\python\python37\lib\site-packages\flask\_compat.py", line 39, in reraise
    raise value
  File "c:\users\aevix\appdata\local\programs\python\python37\lib\site-packages\flask\app.py", line 1949, in full_dispatch_request
    rv = self.dispatch_request()
  File "c:\users\aevix\appdata\local\programs\python\python37\lib\site-packages\flask\app.py", line 1935, in dispatch_request
    return self.view_functions[rule.endpoint](**req.view_args)
  File "c:\users\aevix\appdata\local\programs\python\python37\lib\site-packages\flask_login\utils.py", line 261, in decorated_view
    return func(*args, **kwargs)
  File "C:\Users\Aevix\VSC practice project\item_tracker\app\routes.py", line 28, in index
    posts=posts.items, next_url=next_url,prev_url=prev_url)
  File "c:\users\aevix\appdata\local\programs\python\python37\lib\site-packages\flask\templating.py", line 140, in render_template
    ctx.app,
  File "c:\users\aevix\appdata\local\programs\python\python37\lib\site-packages\flask\templating.py", line 120, in _render
    rv = template.render(context)
  File "c:\users\aevix\appdata\local\programs\python\python37\lib\site-packages\jinja2\asyncsupport.py", line 76, in render
    return original_render(self, *args, **kwargs)
  File "c:\users\aevix\appdata\local\programs\python\python37\lib\site-packages\jinja2\environment.py", line 1008, in render
    return self.environment.handle_exception(exc_info, True)
  File "c:\users\aevix\appdata\local\programs\python\python37\lib\site-packages\jinja2\environment.py", line 780, in handle_exception
    reraise(exc_type, exc_value, tb)
  File "c:\users\aevix\appdata\local\programs\python\python37\lib\site-packages\jinja2\_compat.py", line 37, in reraise
    raise value.with_traceback(tb)
  File "C:\Users\Aevix\VSC practice project\item_tracker\app\templates\index.html", line 1, in top-level template code
    {% extends "base.html" %}
  File "c:\users\aevix\appdata\local\programs\python\python37\lib\site-packages\jinja2\environment.py", line 1005, in render
    return concat(self.root_render_func(self.new_context(vars)))
  File "C:\Users\Aevix\VSC practice project\item_tracker\app\templates\index.html", line 14, in root
    </p>
  File "C:\Users\Aevix\VSC practice project\item_tracker\app\templates\base.html", line 55, in root
  File "C:\Users\Aevix\VSC practice project\item_tracker\app\templates\index.html", line 33, in block_content
  File "c:\users\aevix\appdata\local\programs\python\python37\lib\site-packages\jinja2\environment.py", line 430, in getattr
    return getattr(obj, attribute)
jinja2.exceptions.UndefinedError: 'app.forms.PostForm object' has no attribute 'poster'
2020-03-04 18:03:59,257 INFO: Microblog startup [in C:\Users\Aevix\VSC practice project\item_tracker\app\__init__.py:44]
2020-03-04 18:05:51,112 INFO: Microblog startup [in C:\Users\Aevix\VSC practice project\item_tracker\app\__init__.py:44]
2020-03-04 18:07:46,005 INFO: Microblog startup [in C:\Users\Aevix\VSC practice project\item_tracker\app\__init__.py:44]
2020-03-04 18:07:57,246 ERROR: Exception on /user/yuhyun934 [GET] [in c:\users\aevix\appdata\local\programs\python\python37\lib\site-packages\flask\app.py:1891]
Traceback (most recent call last):
  File "c:\users\aevix\appdata\local\programs\python\python37\lib\site-packages\flask\app.py", line 2446, in wsgi_app
    response = self.full_dispatch_request()
  File "c:\users\aevix\appdata\local\programs\python\python37\lib\site-packages\flask\app.py", line 1951, in full_dispatch_request
    rv = self.handle_user_exception(e)
  File "c:\users\aevix\appdata\local\programs\python\python37\lib\site-packages\flask\app.py", line 1820, in handle_user_exception
    reraise(exc_type, exc_value, tb)
  File "c:\users\aevix\appdata\local\programs\python\python37\lib\site-packages\flask\_compat.py", line 39, in reraise
    raise value
  File "c:\users\aevix\appdata\local\programs\python\python37\lib\site-packages\flask\app.py", line 1949, in full_dispatch_request
    rv = self.dispatch_request()
  File "c:\users\aevix\appdata\local\programs\python\python37\lib\site-packages\flask\app.py", line 1935, in dispatch_request
    return self.view_functions[rule.endpoint](**req.view_args)
  File "c:\users\aevix\appdata\local\programs\python\python37\lib\site-packages\flask_login\utils.py", line 261, in decorated_view
    return func(*args, **kwargs)
  File "C:\Users\Aevix\VSC practice project\item_tracker\app\routes.py", line 78, in user
    return render_template('user.html', user=user, posts=posts.items, next_url=next_url, prev_url=prev_url)
  File "c:\users\aevix\appdata\local\programs\python\python37\lib\site-packages\flask\templating.py", line 140, in render_template
    ctx.app,
  File "c:\users\aevix\appdata\local\programs\python\python37\lib\site-packages\flask\templating.py", line 120, in _render
    rv = template.render(context)
  File "c:\users\aevix\appdata\local\programs\python\python37\lib\site-packages\jinja2\asyncsupport.py", line 76, in render
    return original_render(self, *args, **kwargs)
  File "c:\users\aevix\appdata\local\programs\python\python37\lib\site-packages\jinja2\environment.py", line 1008, in render
    return self.environment.handle_exception(exc_info, True)
  File "c:\users\aevix\appdata\local\programs\python\python37\lib\site-packages\jinja2\environment.py", line 780, in handle_exception
    reraise(exc_type, exc_value, tb)
  File "c:\users\aevix\appdata\local\programs\python\python37\lib\site-packages\jinja2\_compat.py", line 37, in reraise
    raise value.with_traceback(tb)
  File "C:\Users\Aevix\VSC practice project\item_tracker\app\templates\user.html", line 1, in top-level template code
    {% extends "base.html" %}
  File "c:\users\aevix\appdata\local\programs\python\python37\lib\site-packages\jinja2\environment.py", line 1005, in render
    return concat(self.root_render_func(self.new_context(vars)))
  File "C:\Users\Aevix\VSC practice project\item_tracker\app\templates\user.html", line 14, in root
    {% elif not current_user.is_following(user) %}
  File "C:\Users\Aevix\VSC practice project\item_tracker\app\templates\base.html", line 55, in root
  File "C:\Users\Aevix\VSC practice project\item_tracker\app\templates\user.html", line 28, in block_content
    {% endif %}
  File "c:\users\aevix\appdata\local\programs\python\python37\lib\site-packages\jinja2\runtime.py", line 262, in call
    return __obj(*args, **kwargs)
  File "c:\users\aevix\appdata\local\programs\python\python37\lib\site-packages\jinja2\runtime.py", line 630, in _fail_with_undefined_error
    raise self._undefined_exception(hint)
jinja2.exceptions.UndefinedError: 'app.models.User object' has no attribute 'avatars'
2020-03-04 18:27:07,178 INFO: Microblog startup [in C:\Users\Aevix\VSC practice project\item_tracker\app\__init__.py:44]
2020-03-04 18:27:25,711 INFO: Microblog startup [in C:\Users\Aevix\VSC practice project\item_tracker\app\__init__.py:44]
2020-03-04 19:45:30,339 INFO: Microblog startup [in C:\Users\Aevix\VSC practice project\item_tracker\app\__init__.py:44]
2020-03-04 19:53:39,438 INFO: Microblog startup [in C:\Users\Aevix\VSC practice project\item_tracker\app\__init__.py:43]
2020-03-04 19:53:47,932 ERROR: Exception on /user/yuhyun [GET] [in c:\users\aevix\appdata\local\programs\python\python37\lib\site-packages\flask\app.py:1891]
Traceback (most recent call last):
  File "c:\users\aevix\appdata\local\programs\python\python37\lib\site-packages\flask\app.py", line 2446, in wsgi_app
    response = self.full_dispatch_request()
  File "c:\users\aevix\appdata\local\programs\python\python37\lib\site-packages\flask\app.py", line 1951, in full_dispatch_request
    rv = self.handle_user_exception(e)
  File "c:\users\aevix\appdata\local\programs\python\python37\lib\site-packages\flask\app.py", line 1820, in handle_user_exception
    reraise(exc_type, exc_value, tb)
  File "c:\users\aevix\appdata\local\programs\python\python37\lib\site-packages\flask\_compat.py", line 39, in reraise
    raise value
  File "c:\users\aevix\appdata\local\programs\python\python37\lib\site-packages\flask\app.py", line 1949, in full_dispatch_request
    rv = self.dispatch_request()
  File "c:\users\aevix\appdata\local\programs\python\python37\lib\site-packages\flask\app.py", line 1935, in dispatch_request
    return self.view_functions[rule.endpoint](**req.view_args)
  File "c:\users\aevix\appdata\local\programs\python\python37\lib\site-packages\flask_login\utils.py", line 261, in decorated_view
    return func(*args, **kwargs)
  File "C:\Users\Aevix\VSC practice project\item_tracker\app\routes.py", line 79, in user
    return render_template('user.html', user=user, posts=posts.items, next_url=next_url, prev_url=prev_url, current_page=post.page, pages=post.pages)
NameError: name 'post' is not defined
2020-03-04 19:54:23,594 INFO: Microblog startup [in C:\Users\Aevix\VSC practice project\item_tracker\app\__init__.py:43]
