2020-02-03 23:21:47,647 ERROR: Exception on /index [GET] [in c:\users\april\documents\flask\item_tracker\venv\lib\site-packages\flask\app.py:1891]
Traceback (most recent call last):
  File "c:\users\april\documents\flask\item_tracker\venv\lib\site-packages\flask\app.py", line 2446, in wsgi_app
    response = self.full_dispatch_request()
  File "c:\users\april\documents\flask\item_tracker\venv\lib\site-packages\flask\app.py", line 1951, in full_dispatch_request
    rv = self.handle_user_exception(e)
  File "c:\users\april\documents\flask\item_tracker\venv\lib\site-packages\flask\app.py", line 1820, in handle_user_exception
    reraise(exc_type, exc_value, tb)
  File "c:\users\april\documents\flask\item_tracker\venv\lib\site-packages\flask\_compat.py", line 39, in reraise
    raise value
  File "c:\users\april\documents\flask\item_tracker\venv\lib\site-packages\flask\app.py", line 1949, in full_dispatch_request
    rv = self.dispatch_request()
  File "c:\users\april\documents\flask\item_tracker\venv\lib\site-packages\flask\app.py", line 1935, in dispatch_request
    return self.view_functions[rule.endpoint](**req.view_args)
  File "c:\users\april\documents\flask\item_tracker\venv\lib\site-packages\flask_login\utils.py", line 261, in decorated_view
    return func(*args, **kwargs)
  File "C:\Users\April\Documents\GitHub\item_tracker\app\routes.py", line 14, in index
    return render_template('index.html',title='Home', posts=posts)
NameError: name 'posts' is not defined
2020-02-03 23:21:50,425 ERROR: Exception on /index [GET] [in c:\users\april\documents\flask\item_tracker\venv\lib\site-packages\flask\app.py:1891]
Traceback (most recent call last):
  File "c:\users\april\documents\flask\item_tracker\venv\lib\site-packages\flask\app.py", line 2446, in wsgi_app
    response = self.full_dispatch_request()
  File "c:\users\april\documents\flask\item_tracker\venv\lib\site-packages\flask\app.py", line 1951, in full_dispatch_request
    rv = self.handle_user_exception(e)
  File "c:\users\april\documents\flask\item_tracker\venv\lib\site-packages\flask\app.py", line 1820, in handle_user_exception
    reraise(exc_type, exc_value, tb)
  File "c:\users\april\documents\flask\item_tracker\venv\lib\site-packages\flask\_compat.py", line 39, in reraise
    raise value
  File "c:\users\april\documents\flask\item_tracker\venv\lib\site-packages\flask\app.py", line 1949, in full_dispatch_request
    rv = self.dispatch_request()
  File "c:\users\april\documents\flask\item_tracker\venv\lib\site-packages\flask\app.py", line 1935, in dispatch_request
    return self.view_functions[rule.endpoint](**req.view_args)
  File "c:\users\april\documents\flask\item_tracker\venv\lib\site-packages\flask_login\utils.py", line 261, in decorated_view
    return func(*args, **kwargs)
  File "C:\Users\April\Documents\GitHub\item_tracker\app\routes.py", line 14, in index
    return render_template('index.html',title='Home', posts=posts)
NameError: name 'posts' is not defined
2020-02-03 23:25:38,559 INFO: Microblog startup [in C:\Users\April\Documents\GitHub\item_tracker\app\__init__.py:44]
2020-02-03 23:25:44,080 ERROR: Exception on / [GET] [in c:\users\april\documents\flask\item_tracker\venv\lib\site-packages\flask\app.py:1891]
Traceback (most recent call last):
  File "c:\users\april\documents\flask\item_tracker\venv\lib\site-packages\flask\app.py", line 2446, in wsgi_app
    response = self.full_dispatch_request()
  File "c:\users\april\documents\flask\item_tracker\venv\lib\site-packages\flask\app.py", line 1951, in full_dispatch_request
    rv = self.handle_user_exception(e)
  File "c:\users\april\documents\flask\item_tracker\venv\lib\site-packages\flask\app.py", line 1820, in handle_user_exception
    reraise(exc_type, exc_value, tb)
  File "c:\users\april\documents\flask\item_tracker\venv\lib\site-packages\flask\_compat.py", line 39, in reraise
    raise value
  File "c:\users\april\documents\flask\item_tracker\venv\lib\site-packages\flask\app.py", line 1949, in full_dispatch_request
    rv = self.dispatch_request()
  File "c:\users\april\documents\flask\item_tracker\venv\lib\site-packages\flask\app.py", line 1935, in dispatch_request
    return self.view_functions[rule.endpoint](**req.view_args)
  File "c:\users\april\documents\flask\item_tracker\venv\lib\site-packages\flask_login\utils.py", line 261, in decorated_view
    return func(*args, **kwargs)
  File "C:\Users\April\Documents\GitHub\item_tracker\app\routes.py", line 14, in index
    return render_template('index.html',title='Home', posts=posts)
NameError: name 'posts' is not defined
2020-02-03 23:25:52,415 ERROR: Exception on / [GET] [in c:\users\april\documents\flask\item_tracker\venv\lib\site-packages\flask\app.py:1891]
Traceback (most recent call last):
  File "c:\users\april\documents\flask\item_tracker\venv\lib\site-packages\flask\app.py", line 2446, in wsgi_app
    response = self.full_dispatch_request()
  File "c:\users\april\documents\flask\item_tracker\venv\lib\site-packages\flask\app.py", line 1951, in full_dispatch_request
    rv = self.handle_user_exception(e)
  File "c:\users\april\documents\flask\item_tracker\venv\lib\site-packages\flask\app.py", line 1820, in handle_user_exception
    reraise(exc_type, exc_value, tb)
  File "c:\users\april\documents\flask\item_tracker\venv\lib\site-packages\flask\_compat.py", line 39, in reraise
    raise value
  File "c:\users\april\documents\flask\item_tracker\venv\lib\site-packages\flask\app.py", line 1949, in full_dispatch_request
    rv = self.dispatch_request()
  File "c:\users\april\documents\flask\item_tracker\venv\lib\site-packages\flask\app.py", line 1935, in dispatch_request
    return self.view_functions[rule.endpoint](**req.view_args)
  File "c:\users\april\documents\flask\item_tracker\venv\lib\site-packages\flask_login\utils.py", line 261, in decorated_view
    return func(*args, **kwargs)
  File "C:\Users\April\Documents\GitHub\item_tracker\app\routes.py", line 14, in index
    return render_template('index.html',title='Home', posts=posts)
NameError: name 'posts' is not defined
2020-02-03 23:26:33,299 INFO: Microblog startup [in C:\Users\April\Documents\GitHub\item_tracker\app\__init__.py:44]
2020-02-03 23:26:45,105 ERROR: Exception on / [GET] [in c:\users\april\documents\flask\item_tracker\venv\lib\site-packages\flask\app.py:1891]
Traceback (most recent call last):
  File "c:\users\april\documents\flask\item_tracker\venv\lib\site-packages\flask\app.py", line 2446, in wsgi_app
    response = self.full_dispatch_request()
  File "c:\users\april\documents\flask\item_tracker\venv\lib\site-packages\flask\app.py", line 1951, in full_dispatch_request
    rv = self.handle_user_exception(e)
  File "c:\users\april\documents\flask\item_tracker\venv\lib\site-packages\flask\app.py", line 1820, in handle_user_exception
    reraise(exc_type, exc_value, tb)
  File "c:\users\april\documents\flask\item_tracker\venv\lib\site-packages\flask\_compat.py", line 39, in reraise
    raise value
  File "c:\users\april\documents\flask\item_tracker\venv\lib\site-packages\flask\app.py", line 1949, in full_dispatch_request
    rv = self.dispatch_request()
  File "c:\users\april\documents\flask\item_tracker\venv\lib\site-packages\flask\app.py", line 1935, in dispatch_request
    return self.view_functions[rule.endpoint](**req.view_args)
  File "c:\users\april\documents\flask\item_tracker\venv\lib\site-packages\flask_login\utils.py", line 261, in decorated_view
    return func(*args, **kwargs)
  File "C:\Users\April\Documents\GitHub\item_tracker\app\routes.py", line 14, in index
    return render_template('index.html',title='Home', posts=posts)
NameError: name 'posts' is not defined
2020-02-03 23:28:32,212 INFO: Microblog startup [in C:\Users\April\Documents\GitHub\item_tracker\app\__init__.py:44]
2020-02-03 23:28:47,510 ERROR: Exception on /index [GET] [in c:\users\april\documents\flask\item_tracker\venv\lib\site-packages\flask\app.py:1891]
Traceback (most recent call last):
  File "c:\users\april\documents\flask\item_tracker\venv\lib\site-packages\flask\app.py", line 2446, in wsgi_app
    response = self.full_dispatch_request()
  File "c:\users\april\documents\flask\item_tracker\venv\lib\site-packages\flask\app.py", line 1951, in full_dispatch_request
    rv = self.handle_user_exception(e)
  File "c:\users\april\documents\flask\item_tracker\venv\lib\site-packages\flask\app.py", line 1820, in handle_user_exception
    reraise(exc_type, exc_value, tb)
  File "c:\users\april\documents\flask\item_tracker\venv\lib\site-packages\flask\_compat.py", line 39, in reraise
    raise value
  File "c:\users\april\documents\flask\item_tracker\venv\lib\site-packages\flask\app.py", line 1949, in full_dispatch_request
    rv = self.dispatch_request()
  File "c:\users\april\documents\flask\item_tracker\venv\lib\site-packages\flask\app.py", line 1935, in dispatch_request
    return self.view_functions[rule.endpoint](**req.view_args)
  File "c:\users\april\documents\flask\item_tracker\venv\lib\site-packages\flask_login\utils.py", line 261, in decorated_view
    return func(*args, **kwargs)
  File "C:\Users\April\Documents\GitHub\item_tracker\app\routes.py", line 31, in index
    return render_template('index.html',title='Home', posts=posts)
NameError: name 'posts' is not defined
